Workbook

Sheet Guidance

Sheet Version
B8: Version information
B10: Security classification
B11: Version
B12: Dated
B13: Approval

Sheet ISO27001 Annex A Applicability
F7: Terms used
B8: Information security management systems: Requirements | F8: ISMS: Information Security Management System
B9: Note: Only those controls that are listed in Annex A of the ISO/IEC 27001 standard are shown here.
B12: AREA/SECTION | C12: CONTROL | D12: CONTROL APPLICABLE? | E12: CONTROL IMPLEMENTED? | F12: JUSTIFICATION FOR INCLUSION OR EXCLUSION | G12: COMMENTS
B14: A.5 Organizational controls | D14: Yes | E14: Partially implemented | F14: Applicable to Digital Horizons Bank banking, regulatory, customer, personnel, technology, supplier or continuity risk; inclusion is supported by the risk assessment and legal/regulatory context. | G14: Current state includes documented gaps; treatment is tracked in Risk Register R-01 to R-09 and linked procedures.
C15: A.5.1 Policies for information security | D15: Yes | E15: Partially implemented | F15: Applicable to Digital Horizons Bank banking, regulatory, customer, personnel, technology, supplier or continuity risk; inclusion is supported by the risk assessment and legal/regulatory context. | G15: Current state includes documented gaps; treatment is tracked in Risk Register R-01 to R-09 and linked procedures.
C16: A.5.2 Information security roles and responsibilities | D16: Yes | E16: Partially implemented | F16: Applicable to Digital Horizons Bank banking, regulatory, customer, personnel, technology, supplier or continuity risk; inclusion is supported by the risk assessment and legal/regulatory context. | G16: Current state includes documented gaps; treatment is tracked in Risk Register R-01 to R-09 and linked procedures.
C17: A.5.3 Segregation of duties | D17: Yes | E17: Partially implemented | F17: Applicable to Digital Horizons Bank banking, regulatory, customer, personnel, technology, supplier or continuity risk; inclusion is supported by the risk assessment and legal/regulatory context. | G17: Current state includes documented gaps; treatment is tracked in Risk Register R-01 to R-09 and linked procedures.
C18: A.5.4 Management responsibilities | D18: Yes | E18: Partially implemented | F18: Applicable to Digital Horizons Bank banking, regulatory, customer, personnel, technology, supplier or continuity risk; inclusion is supported by the risk assessment and legal/regulatory context. | G18: Current state includes documented gaps; treatment is tracked in Risk Register R-01 to R-09 and linked procedures.
C19: A.5.5 Contact with authorities | D19: Yes | E19: Partially implemented | F19: Applicable to Digital Horizons Bank banking, regulatory, customer, personnel, technology, supplier or continuity risk; inclusion is supported by the risk assessment and legal/regulatory context. | G19: Current state includes documented gaps; treatment is tracked in Risk Register R-01 to R-09 and linked procedures.
C20: A.5.6 Contact with special interest groups | D20: Yes | E20: Partially implemented | F20: Applicable to Digital Horizons Bank banking, regulatory, customer, personnel, technology, supplier or continuity risk; inclusion is supported by the risk assessment and legal/regulatory context. | G20: Current state includes documented gaps; treatment is tracked in Risk Register R-01 to R-09 and linked procedures.
C21: A.5.7 Threat intelligence | D21: Yes | E21: Partially implemented | F21: Applicable to Digital Horizons Bank banking, regulatory, customer, personnel, technology, supplier or continuity risk; inclusion is supported by the risk assessment and legal/regulatory context. | G21: Current state includes documented gaps; treatment is tracked in Risk Register R-01 to R-09 and linked procedures.
C22: A.5.8 Information security in project management | D22: Yes | E22: Partially implemented | F22: Applicable to Digital Horizons Bank banking, regulatory, customer, personnel, technology, supplier or continuity risk; inclusion is supported by the risk assessment and legal/regulatory context. | G22: Current state includes documented gaps; treatment is tracked in Risk Register R-01 to R-09 and linked procedures.
C23: A.5.9 Inventory of information and other associated assets | D23: Yes | E23: Partially implemented | F23: Applicable to Digital Horizons Bank banking, regulatory, customer, personnel, technology, supplier or continuity risk; inclusion is supported by the risk assessment and legal/regulatory context. | G23: Current state includes documented gaps; treatment is tracked in Risk Register R-01 to R-09 and linked procedures.
C24: A.5.10 Acceptable use of information and other associated assets | D24: Yes | E24: Partially implemented | F24: Applicable to Digital Horizons Bank banking, regulatory, customer, personnel, technology, supplier or continuity risk; inclusion is supported by the risk assessment and legal/regulatory context. | G24: Current state includes documented gaps; treatment is tracked in Risk Register R-01 to R-09 and linked procedures.
C25: A.5.11 Return of assets | D25: Yes | E25: Partially implemented | F25: Applicable to Digital Horizons Bank banking, regulatory, customer, personnel, technology, supplier or continuity risk; inclusion is supported by the risk assessment and legal/regulatory context. | G25: Current state includes documented gaps; treatment is tracked in Risk Register R-01 to R-09 and linked procedures.
C26: A.5.12 Classification of information | D26: Yes | E26: Partially implemented | F26: Applicable to Digital Horizons Bank banking, regulatory, customer, personnel, technology, supplier or continuity risk; inclusion is supported by the risk assessment and legal/regulatory context. | G26: Current state includes documented gaps; treatment is tracked in Risk Register R-01 to R-09 and linked procedures.
... C53: Totals: | D53: Yes | E53: Partially implemented | F53: Applicable to Digital Horizons Bank banking, regulatory, customer, personnel, technology, supplier or continuity risk; inclusion is supported by the risk assessment and legal/regulatory context. | G53: Current state includes documented gaps; treatment is tracked in Risk Register R-01 to R-09 and linked procedures.
B55: A.6 People controls | D55: Yes | E55: Partially implemented | F55: Applicable to Digital Horizons Bank banking, regulatory, customer, personnel, technology, supplier or continuity risk; inclusion is supported by the risk assessment and legal/regulatory context. | G55: Current state includes documented gaps; treatment is tracked in Risk Register R-01 to R-09 and linked procedures.
C56: A.6.1 Screening | D56: Yes | E56: Partially implemented | F56: Applicable to Digital Horizons Bank banking, regulatory, customer, personnel, technology, supplier or continuity risk; inclusion is supported by the risk assessment and legal/regulatory context. | G56: Current state includes documented gaps; treatment is tracked in Risk Register R-01 to R-09 and linked procedures.
C57: A.6.2 Terms and conditions of employment | D57: Yes | E57: Partially implemented | F57: Applicable to Digital Horizons Bank banking, regulatory, customer, personnel, technology, supplier or continuity risk; inclusion is supported by the risk assessment and legal/regulatory context. | G57: Current state includes documented gaps; treatment is tracked in Risk Register R-01 to R-09 and linked procedures.
C58: A.6.3 Information security awareness, education and training | D58: Yes | E58: Partially implemented | F58: Applicable to Digital Horizons Bank banking, regulatory, customer, personnel, technology, supplier or continuity risk; inclusion is supported by the risk assessment and legal/regulatory context. | G58: Current state includes documented gaps; treatment is tracked in Risk Register R-01 to R-09 and linked procedures.
C59: A.6.4 Disciplinary process | D59: Yes | E59: Partially implemented | F59: Applicable to Digital Horizons Bank banking, regulatory, customer, personnel, technology, supplier or continuity risk; inclusion is supported by the risk assessment and legal/regulatory context. | G59: Current state includes documented gaps; treatment is tracked in Risk Register R-01 to R-09 and linked procedures.
C60: A.6.5 Responsibilities after termination or change of employment | D60: Yes | E60: Partially implemented | F60: Applicable to Digital Horizons Bank banking, regulatory, customer, personnel, technology, supplier or continuity risk; inclusion is supported by the risk assessment and legal/regulatory context. | G60: Current state includes documented gaps; treatment is tracked in Risk Register R-01 to R-09 and linked procedures.
C61: A.6.6 Confidentiality or non-disclosure agreements | D61: Yes | E61: Partially implemented | F61: Applicable to Digital Horizons Bank banking, regulatory, customer, personnel, technology, supplier or continuity risk; inclusion is supported by the risk assessment and legal/regulatory context. | G61: Current state includes documented gaps; treatment is tracked in Risk Register R-01 to R-09 and linked procedures.
C62: A.6.7 Remote working | D62: Yes | E62: Partially implemented | F62: Applicable to Digital Horizons Bank banking, regulatory, customer, personnel, technology, supplier or continuity risk; inclusion is supported by the risk assessment and legal/regulatory context. | G62: Current state includes documented gaps; treatment is tracked in Risk Register R-01 to R-09 and linked procedures.
C63: A.6.8 Information security event reporting | D63: Yes | E63: Partially implemented | F63: Applicable to Digital Horizons Bank banking, regulatory, customer, personnel, technology, supplier or continuity risk; inclusion is supported by the risk assessment and legal/regulatory context. | G63: Current state includes documented gaps; treatment is tracked in Risk Register R-01 to R-09 and linked procedures.
C65: Totals: | D65: Yes | E65: Partially implemented | F65: Applicable to Digital Horizons Bank banking, regulatory, customer, personnel, technology, supplier or continuity risk; inclusion is supported by the risk assessment and legal/regulatory context. | G65: Current state includes documented gaps; treatment is tracked in Risk Register R-01 to R-09 and linked procedures.
B67: A.7 Physical controls | D67: Yes | E67: Partially implemented | F67: Applicable to Digital Horizons Bank banking, regulatory, customer, personnel, technology, supplier or continuity risk; inclusion is supported by the risk assessment and legal/regulatory context. | G67: Current state includes documented gaps; treatment is tracked in Risk Register R-01 to R-09 and linked procedures.
C68: A.7.1 Physical security perimeters | D68: Yes | E68: Partially implemented | F68: Applicable to Digital Horizons Bank banking, regulatory, customer, personnel, technology, supplier or continuity risk; inclusion is supported by the risk assessment and legal/regulatory context. | G68: Current state includes documented gaps; treatment is tracked in Risk Register R-01 to R-09 and linked procedures.
C69: A.7.2 Physical entry | D69: Yes | E69: Partially implemented | F69: Applicable to Digital Horizons Bank banking, regulatory, customer, personnel, technology, supplier or continuity risk; inclusion is supported by the risk assessment and legal/regulatory context. | G69: Current state includes documented gaps; treatment is tracked in Risk Register R-01 to R-09 and linked procedures.
C70: A.7.3 Securing offices, rooms and facilities | D70: Yes | E70: Partially implemented | F70: Applicable to Digital Horizons Bank banking, regulatory, customer, personnel, technology, supplier or continuity risk; inclusion is supported by the risk assessment and legal/regulatory context. | G70: Current state includes documented gaps; treatment is tracked in Risk Register R-01 to R-09 and linked procedures.
C71: A.7.4 Physical security monitoring | D71: Yes | E71: Partially implemented | F71: Applicable to Digital Horizons Bank banking, regulatory, customer, personnel, technology, supplier or continuity risk; inclusion is supported by the risk assessment and legal/regulatory context. | G71: Current state includes documented gaps; treatment is tracked in Risk Register R-01 to R-09 and linked procedures.
C72: A.7.5 Protecting against physical and environmental threats | D72: Yes | E72: Partially implemented | F72: Applicable to Digital Horizons Bank banking, regulatory, customer, personnel, technology, supplier or continuity risk; inclusion is supported by the risk assessment and legal/regulatory context. | G72: Current state includes documented gaps; treatment is tracked in Risk Register R-01 to R-09 and linked procedures.
C73: A.7.6 Working in secure areas | D73: Yes | E73: Partially implemented | F73: Applicable to Digital Horizons Bank banking, regulatory, customer, personnel, technology, supplier or continuity risk; inclusion is supported by the risk assessment and legal/regulatory context. | G73: Current state includes documented gaps; treatment is tracked in Risk Register R-01 to R-09 and linked procedures.
C74: A.7.7 Clear desk and clear screen | D74: Yes | E74: Partially implemented | F74: Applicable to Digital Horizons Bank banking, regulatory, customer, personnel, technology, supplier or continuity risk; inclusion is supported by the risk assessment and legal/regulatory context. | G74: Current state includes documented gaps; treatment is tracked in Risk Register R-01 to R-09 and linked procedures.
C75: A.7.8 Equipment siting and protection | D75: Yes | E75: Partially implemented | F75: Applicable to Digital Horizons Bank banking, regulatory, customer, personnel, technology, supplier or continuity risk; inclusion is supported by the risk assessment and legal/regulatory context. | G75: Current state includes documented gaps; treatment is tracked in Risk Register R-01 to R-09 and linked procedures.
C76: A.7.9 Security of assets off-premises | D76: Yes | E76: Partially implemented | F76: Applicable to Digital Horizons Bank banking, regulatory, customer, personnel, technology, supplier or continuity risk; inclusion is supported by the risk assessment and legal/regulatory context. | G76: Current state includes documented gaps; treatment is tracked in Risk Register R-01 to R-09 and linked procedures.
C77: A.7.10 Storage media | D77: Yes | E77: Partially implemented | F77: Applicable to Digital Horizons Bank banking, regulatory, customer, personnel, technology, supplier or continuity risk; inclusion is supported by the risk assessment and legal/regulatory context. | G77: Current state includes documented gaps; treatment is tracked in Risk Register R-01 to R-09 and linked procedures.
C78: A.7.11 Supporting utilities | D78: Yes | E78: Partially implemented | F78: Applicable to Digital Horizons Bank banking, regulatory, customer, personnel, technology, supplier or continuity risk; inclusion is supported by the risk assessment and legal/regulatory context. | G78: Current state includes documented gaps; treatment is tracked in Risk Register R-01 to R-09 and linked procedures.
...

Sheet ISO27001 Annex A Dashboard
B8: ISO/IEC 27001 Statement of Applicability dashboard
B9: To refresh chart data, click on “Refresh All” on the Data ribbon.
B11: Statement of applicability results
B13: AREA OF STANDARD | C13: NO OF CONTROLS | D13: APPLICABLE CONTROLS | E13: % CONTROLS APPLICABLE | F13: CONTROLS IMPLEMENTED | G13: % APP CONTROLS IMPLEMENTED | I13: ISO/IEC 27001 Annex A controls percentage of controls applicable and implemented radar chart
B14: A.5 Organizational controls | C14: 37 | D14: ='ISO27001 Annex A Applicability'!D53 | E14: =ISO27001ApplicabilityTableResults11[[#This Row],[APPLICABLE CONTROLS]]/ISO27001ApplicabilityTableResults11[[#This Row],[NO OF CONTROLS]] | F14: ='ISO27001 Annex A Applicability'!E53 | G14: =IF(D14=0,1,+F14/D14)
B15: A.6 People controls | C15: 8 | D15: ='ISO27001 Annex A Applicability'!D65 | E15: =ISO27001ApplicabilityTableResults11[[#This Row],[APPLICABLE CONTROLS]]/ISO27001ApplicabilityTableResults11[[#This Row],[NO OF CONTROLS]] | F15: ='ISO27001 Annex A Applicability'!E65 | G15: =IF(D15=0,1,+F15/D15)
B16: A.7 Physical controls | C16: 14 | D16: ='ISO27001 Annex A Applicability'!D83 | E16: =ISO27001ApplicabilityTableResults11[[#This Row],[APPLICABLE CONTROLS]]/ISO27001ApplicabilityTableResults11[[#This Row],[NO OF CONTROLS]] | F16: ='ISO27001 Annex A Applicability'!E83 | G16: =IF(D16=0,1,+F16/D16)
B17: A.8 Technological controls | C17: 34 | D17: ='ISO27001 Annex A Applicability'!D121 | E17: =ISO27001ApplicabilityTableResults11[[#This Row],[APPLICABLE CONTROLS]]/ISO27001ApplicabilityTableResults11[[#This Row],[NO OF CONTROLS]] | F17: ='ISO27001 Annex A Applicability'!E121 | G17: =IF(D17=0,1,+F17/D17)
B18: Total | C18: =SUBTOTAL(109,ISO27001ApplicabilityTableResults11[NO OF CONTROLS]) | D18: =SUBTOTAL(109,ISO27001ApplicabilityTableResults11[APPLICABLE CONTROLS]) | E18: =SUBTOTAL(101,ISO27001ApplicabilityTableResults11[% CONTROLS APPLICABLE]) | F18: =SUBTOTAL(109,ISO27001ApplicabilityTableResults11[CONTROLS IMPLEMENTED]) | G18: =SUBTOTAL(101,ISO27001ApplicabilityTableResults11[% APP CONTROLS IMPLEMENTED])
B22: ISO/IEC 27001 Annex A controls number of controls applicable and implemented
I38: ISO/IEC 27001 Annex A controls percentage of controls applicable and implemented

Sheet ISO27001 Applicability Table
B4: ISO/IEC 27001 Statement of Applicability results
B6: AREA OF STANDARD | C6: NO OF CONTROLS | D6: APPLICABLE CONTROLS | E6: % CONTROLS APPLICABLE | F6: CONTROLS IMPLEMENTED | G6: % APP CONTROLS IMPLEMENTED
B7: A.5 Organizational controls | C7: 37 | D7: ='ISO27001 Annex A Applicability'!D53 | E7: =ISO27001ApplicabilityTableResults[[#This Row],[APPLICABLE CONTROLS]]/ISO27001ApplicabilityTableResults[[#This Row],[NO OF CONTROLS]] | F7: ='ISO27001 Annex A Applicability'!E53 | G7: =IF(D7=0,1,+F7/D7)
B8: A.6 People controls | C8: 8 | D8: ='ISO27001 Annex A Applicability'!D65 | E8: =ISO27001ApplicabilityTableResults[[#This Row],[APPLICABLE CONTROLS]]/ISO27001ApplicabilityTableResults[[#This Row],[NO OF CONTROLS]] | F8: ='ISO27001 Annex A Applicability'!E65 | G8: =IF(D8=0,1,+F8/D8)
B9: A.7 Physical controls | C9: 14 | D9: ='ISO27001 Annex A Applicability'!D83 | E9: =ISO27001ApplicabilityTableResults[[#This Row],[APPLICABLE CONTROLS]]/ISO27001ApplicabilityTableResults[[#This Row],[NO OF CONTROLS]] | F9: ='ISO27001 Annex A Applicability'!E83 | G9: =IF(D9=0,1,+F9/D9)
B10: A.8 Technological controls | C10: 34 | D10: ='ISO27001 Annex A Applicability'!D121 | E10: =ISO27001ApplicabilityTableResults[[#This Row],[APPLICABLE CONTROLS]]/ISO27001ApplicabilityTableResults[[#This Row],[NO OF CONTROLS]] | F10: ='ISO27001 Annex A Applicability'!E121 | G10: =IF(D10=0,1,+F10/D10)
B11: Total | C11: =SUBTOTAL(109,ISO27001ApplicabilityTableResults[NO OF CONTROLS]) | D11: =SUBTOTAL(109,ISO27001ApplicabilityTableResults[APPLICABLE CONTROLS]) | E11: =SUBTOTAL(101,ISO27001ApplicabilityTableResults[% CONTROLS APPLICABLE]) | F11: =SUBTOTAL(109,ISO27001ApplicabilityTableResults[CONTROLS IMPLEMENTED]) | G11: =SUBTOTAL(101,ISO27001ApplicabilityTableResults[% APP CONTROLS IMPLEMENTED])

Sheet ISO27001 Results Chart
B4: ISO/IEC 27001 Annex A Controls Number of Controls Applicable and Implemented
B6: AREA OF STANDARD | C6: APPLICABLE CONTROLS | D6: CONTROLS IMPLEMENTED
B7: A.8 Technological controls | C7: 34 | D7: 34
B8: A.7 Physical controls | C8: 14 | D8: 14
B9: A.6 People controls | C9: 8 | D9: 8
B10: A.5 Organizational controls | C10: 37 | D10: 37

Sheet ISO27001 % Results Chart
B4: ISO/IEC 27001 Annex A Controls Percentage of Controls Applicable and Implemented
B6: AREA OF STANDARD | C6: % APP CONTROLS IMPLEMENTED | D6: % CONTROLS APPLICABLE
B7: A.5 Organizational controls | C7: 1 | D7: 1
B8: A.6 People controls | C8: 1 | D8: 1
B9: A.7 Physical controls | C9: 1 | D9: 1
B10: A.8 Technological controls | C10: 1 | D10: 1

Sheet ISO27001 % Radar Chart
B4: ISO/IEC 27001 Annex A Controls Percentage of Controls Applicable and Implemented Radar Chart
B6: AREA OF STANDARD | C6: % APP CONTROLS IMPLEMENTED | D6: % CONTROLS APPLICABLE
B7: A.5 Organizational controls | C7: 1 | D7: 1
B8: A.6 People controls | C8: 1 | D8: 1
B9: A.7 Physical controls | C9: 1 | D9: 1
B10: A.8 Technological controls | C10: 1 | D10: 1
